Exception: Cannot resume an already running generator

Fatal error: %s
Stack trace:
#0 %s(%d): Generator->next()
#1 [internal function]: gen()
#2 %s(%d): Generator->send(Object(Generator))
#3 {main}
  thrown in %s on line %d